#VRML_SIM R2025a utf8

EXTERNPROTO "https://raw.githubusercontent.com/cyberbotics/webots/R2025a/projects/objects/backgrounds/protos/TexturedBackground.proto"
EXTERNPROTO "https://raw.githubusercontent.com/cyberbotics/webots/R2025a/projects/objects/backgrounds/protos/TexturedBackgroundLight.proto"
EXTERNPROTO "https://raw.githubusercontent.com/cyberbotics/webots/R2025a/projects/objects/floors/protos/RectangleArena.proto"

WorldInfo {
  title "Level 3.2 - Accelerometer Controller"
}

Viewpoint {
  orientation -0.5773502691896258 0.5773502691896258 0.5773502691896258 2.0944
  position 0 0 8
  follow "AccelBot"
}

TexturedBackground {
}

TexturedBackgroundLight {
}

RectangleArena {
  floorSize 4 4
  wallHeight 0.3
}

DEF AccelBot Robot {
  translation 0 0 0.1
  rotation 0 0 1 1.5708
  children [
    Shape {
      appearance PBRAppearance {
        baseColor 0.1 0.5 1
        roughness 1
        metalness 0
      }
      geometry DEF BODY_BOX Box {
        size 0.4 0.2 0.1
      }
    }
    
    Solid {
      translation 0.22 0 0.02
      name "front_marker"
      children [
        Shape {
          appearance PBRAppearance {
            baseColor 1 0 0
            roughness 1
            metalness 0
          }
          geometry Box {
            size 0.05 0.1 0.02
          }
        }
      ]
    }
    
    HingeJoint {
      jointParameters HingeJointParameters {
        axis 0 1 0
        anchor 0 0.12 0
      }
      device [
        RotationalMotor {
          name "left_motor"
        }
      ]
      endPoint Solid {
        translation 0 0.12 0
        rotation 1 0 0 1.5708
        name "left_wheel"
        children [
          DEF WHEEL Shape {
            appearance PBRAppearance {
              baseColor 0.2 0.2 0.2
            }
            geometry Cylinder {
              height 0.04
              radius 0.08
            }
          }
        ]
        boundingObject USE WHEEL
        physics Physics {}
      }
    }
    
    HingeJoint {
      jointParameters HingeJointParameters {
        axis 0 1 0
        anchor 0 -0.12 0
      }
      device [
        RotationalMotor {
          name "right_motor"
        }
      ]
      endPoint Solid {
        translation 0 -0.12 0
        rotation 1 0 0 1.5708
        name "right_wheel"
        children [
          USE WHEEL
        ]
        boundingObject USE WHEEL
        physics Physics {}
      }
    }
    
    BallJoint {
      jointParameters BallJointParameters { anchor -0.15 0 -0.04 }
      endPoint Solid {
        translation -0.15 0 -0.04
        name "ball_wheel_rear"
        children [
          Shape {
            appearance PBRAppearance { baseColor 0.5 0.5 0.5 roughness 0.3 metalness 0.1 }
            geometry Sphere { radius 0.04 }
          }
        ]
        boundingObject Sphere { radius 0.04 }
        physics Physics { density -1 mass 0.1 }
      }
    }
    BallJoint {
      jointParameters BallJointParameters { anchor 0.15 0 -0.04 }
      endPoint Solid {
        translation 0.15 0 -0.04
        name "ball_wheel_front"
        children [
          Shape {
            appearance PBRAppearance { baseColor 0.5 0.5 0.5 roughness 0.3 metalness 0.1 }
            geometry Sphere { radius 0.04 }
          }
        ]
        boundingObject Sphere { radius 0.04 }
        physics Physics { density -1 mass 0.1 }
      }
    }
    
    # Distance Sensors
    DistanceSensor {
      translation 0.2 0 0.06
      rotation 0 0 1 0
      name "ds_front"
      children [
        Shape {
          appearance PBRAppearance {
            baseColor 1 1 0.6
            emissiveColor 0.8 0.8 0
          }
          geometry Box { size 0.05 0.05 0.05 }
        }
      ]
      lookupTable [
        0 0 0
        0.05 50 0
        1.0 1000 0
      ]
      type "infra-red"
      numberOfRays 2
    }
    
    DistanceSensor {
      translation 0.18 0.08 0.06
      rotation 0 0 1 0.785398
      name "ds_front_left"
      children [
        Shape {
          appearance PBRAppearance {
            baseColor 1 1 0.6
            emissiveColor 0.8 0.8 0
          }
          geometry Box { size 0.05 0.05 0.05 }
        }
      ]
      lookupTable [
        0 0 0
        0.05 50 0
        1.0 1000 0
      ]
      type "infra-red"
      numberOfRays 2
    }
    
    DistanceSensor {
      translation 0.18 -0.08 0.06
      rotation 0 0 1 -0.785398
      name "ds_front_right"
      children [
        Shape {
          appearance PBRAppearance {
            baseColor 1 1 0.6
            emissiveColor 0.8 0.8 0
          }
          geometry Box { size 0.05 0.05 0.05 }
        }
      ]
      lookupTable [
        0 0 0
        0.05 50 0
        1.0 1000 0
      ]
      type "infra-red"
      numberOfRays 2
    }
    
    DistanceSensor {
      translation 0 0.11 0.06
      rotation 0 0 1 1.5708
      name "ds_left"
      children [
        Shape {
          appearance PBRAppearance {
            baseColor 1 1 0.6
            emissiveColor 0.8 0.8 0
          }
          geometry Box { size 0.05 0.05 0.05 }
        }
      ]
      lookupTable [
        0 0 0
        0.05 50 0
        1.0 1000 0
      ]
      type "infra-red"
      numberOfRays 2
    }
    
    DistanceSensor {
      translation 0 -0.11 0.06
      rotation 0 0 1 -1.5708
      name "ds_right"
      children [
        Shape {
          appearance PBRAppearance {
            baseColor 1 1 0.6
            emissiveColor 0.8 0.8 0
          }
          geometry Box { size 0.05 0.05 0.05 }
        }
      ]
      lookupTable [
        0 0 0
        0.05 50 0
        1.0 1000 0
      ]
      type "infra-red"
      numberOfRays 2
    }
    
    Accelerometer {
      name "accelerometer"
    }
  ]
  
  name "AccelBot"
  boundingObject USE BODY_BOX
  physics Physics {
    density -1
    mass 5
  }
  controller "<extern>"
}
