#VRML_SIM R2025a utf8

EXTERNPROTO "https://raw.githubusercontent.com/cyberbotics/webots/R2025a/projects/objects/backgrounds/protos/TexturedBackground.proto"
EXTERNPROTO "https://raw.githubusercontent.com/cyberbotics/webots/R2025a/projects/objects/backgrounds/protos/TexturedBackgroundLight.proto"
EXTERNPROTO "https://raw.githubusercontent.com/cyberbotics/webots/R2025a/projects/objects/floors/protos/RectangleArena.proto"

WorldInfo {
}

Viewpoint {
  orientation -0.4891598184709118 0.48916047717159244 0.7221112792130897 1.8907729068043837
  position 0.06248528188425385 -2.7531282549238454 7.193639067955213
}

TexturedBackground {
}

TexturedBackgroundLight {
}

RectangleArena {
  floorSize 6 6
}

# Target marker at 1 meter distance
DEF TARGET_MARKER Solid {
  translation 0 2.7 0.01
  children [
    Shape {
      appearance PBRAppearance {
        baseColor 0 1 0
        roughness 1
        metalness 0
      }
      geometry Box {
        size 1.0 0.05 0.05
      }
    }
  ]
  name "target_1m"
}

# --- Level 1.1: Robot with Wheel Encoders ---
DEF EncoderBot Robot {
  translation 0 -2.7 0.1
  # Rotate 90 degrees around Z-axis (0 0 1) to make it face Y-axis direction
  rotation 0 0 1 1.5708 
  children [
    # 1. Body
    Shape {
      appearance PBRAppearance {
        baseColor 0.1 0.5 1  # Light blue color
        roughness 1
        metalness 0
      }
      geometry DEF BODY_BOX Box {
        size 0.4 0.2 0.1
      }
    }
    # 2. Left Wheel with Encoder
    HingeJoint {
      jointParameters HingeJointParameters {
        axis 0 1 0
        anchor 0 0.12 0
      }
      device [
        RotationalMotor {
          name "left_motor"  # Motor name for ROS
        }
        PositionSensor {
          name "left_wheel_sensor"  # Encoder for odometry
        }
      ]
      endPoint Solid {
        translation 0 0.12 0
        rotation 1 0 0 1.5708
        name "left_wheel"  # Unique name to avoid conflicts
        children [
          DEF WHEEL Shape {
            appearance PBRAppearance {
              baseColor 0.2 0.2 0.2 # Dark gray color
            }
            geometry Cylinder {
              height 0.04
              radius 0.08
            }
          }
        ]
        boundingObject USE WHEEL
        physics Physics {}
      }
    }
    # 3. Right Wheel with Encoder
    HingeJoint {
      jointParameters HingeJointParameters {
        axis 0 1 0
        anchor 0 -0.12 0
      }
      device [
        RotationalMotor {
          name "right_motor" # Motor name for ROS
        }
        PositionSensor {
          name "right_wheel_sensor"  # Encoder for odometry
        }
      ]
      endPoint Solid {
        translation 0 -0.12 0
        rotation 1 0 0 1.5708
        name "right_wheel" # Unique name to avoid conflicts
        children [
          USE WHEEL
        ]
        boundingObject USE WHEEL
        physics Physics {}
      }
    }
    # 4. Ball Wheels - For stability and balance (Front and Rear)
    BallJoint {
      jointParameters BallJointParameters { anchor -0.15 0 -0.04 }
      endPoint Solid {
        translation -0.15 0 -0.04
        name "ball_wheel_rear"
        children [
          Shape {
            appearance PBRAppearance { baseColor 0.5 0.5 0.5 roughness 0.3 metalness 0.1 }
            geometry Sphere { radius 0.04 }
          }
        ]
        boundingObject Sphere { radius 0.04 }
        physics Physics { density -1 mass 0.1 }
      }
    }
    BallJoint {
      jointParameters BallJointParameters { anchor 0.15 0 -0.04 }
      endPoint Solid {
        translation 0.15 0 -0.04
        name "ball_wheel_front"
        children [
          Shape {
            appearance PBRAppearance { baseColor 0.5 0.5 0.5 roughness 0.3 metalness 0.1 }
            geometry Sphere { radius 0.04 }
          }
        ]
        boundingObject Sphere { radius 0.04 }
        physics Physics {
         # Low friction for smooth rolling
         density -1 mass 0.1ß
      }
    }
  }
    # 5. Front Marker/Nose
    Transform {
      translation 0.2 0 0 # Positioned at the front edge (X=0.2)
      children [
        Shape {
          appearance PBRAppearance {
            baseColor 0 1 0 # Green color
            roughness 1
            metalness 0
          }
          geometry Box {
            size 0.05 0.1 0.05 # Small rectangular piece protruding forward
          }
        }
      ]
    }
  ]
  # Main body physics
  boundingObject USE BODY_BOX
  physics Physics {
    density -1
    mass 5
  }
  
  # ROS connection
  name "EncoderBot"
  controller "<extern>"
}
