#VRML_SIM R2025a utf8

EXTERNPROTO "https://raw.githubusercontent.com/cyberbotics/webots/R2025a/projects/objects/backgrounds/protos/TexturedBackground.proto"
EXTERNPROTO "https://raw.githubusercontent.com/cyberbotics/webots/R2025a/projects/objects/backgrounds/protos/TexturedBackgroundLight.proto"
EXTERNPROTO "https://raw.githubusercontent.com/cyberbotics/webots/R2025a/projects/objects/floors/protos/RectangleArena.proto"

WorldInfo {
  title "Level 5.2 - SLAM with Odometry"
}
Viewpoint {
  orientation -0.5773502691896258 0.5773502691896258 0.5773502691896258 2.0944
  position -1.2971864247334805e-05 -1.2971900928750004e-05 7.4124615123039765
  follow "SlamBot"
}
TexturedBackground {
}
TexturedBackgroundLight {
}
RectangleArena {
  floorSize 5 5
  wallHeight 0.4
}
Solid {
  translation 1.5 1.5 0.25
  children [
    Shape {
      appearance PBRAppearance {
        baseColor 0.8 0.2 0.2
        roughness 1
        metalness 0
      }
      geometry Cylinder {
        height 0.5
        radius 0.25
      }
    }
  ]
  name "obstacle_1"
  boundingObject Cylinder {
    height 0.5
    radius 0.25
  }
}
Solid {
  translation -1.5 1.5 0.25
  children [
    Shape {
      appearance PBRAppearance {
        baseColor 0.2 0.8 0.2
        roughness 1
        metalness 0
      }
      geometry Cylinder {
        height 0.5
        radius 0.25
      }
    }
  ]
  name "obstacle_2"
  boundingObject Cylinder {
    height 0.5
    radius 0.25
  }
}
Solid {
  translation -1.8 0 0.25
  children [
    Shape {
      appearance PBRAppearance {
        baseColor 0.2 0.2 0.8
        roughness 1
        metalness 0
      }
      geometry Box {
        size 0.4 1 0.5
      }
    }
  ]
  name "obstacle_3"
  boundingObject Box {
    size 0.4 1 0.5
  }
}
Solid {
  translation 1.8 0 0.25
  children [
    Shape {
      appearance PBRAppearance {
        baseColor 0.8 0.8 0.2
        roughness 1
        metalness 0
      }
      geometry Box {
        size 0.4 1 0.5
      }
    }
  ]
  name "obstacle_4"
  boundingObject Box {
    size 0.4 1 0.5
  }
}
Solid {
  translation 0 1.2 0.2
  children [
    Shape {
      appearance PBRAppearance {
        baseColor 0.9 0.3 0.1
        roughness 1
        metalness 0
      }
      geometry Box {
        size 1.5 0.3 0.4
      }
    }
  ]
  name "obstacle_5"
  boundingObject Box {
    size 1.5 0.3 0.4
  }
}
Solid {
  translation 0.8 -1.5 0.15
  children [
    Shape {
      appearance PBRAppearance {
        baseColor 0.3 0.9 0.8
        roughness 1
        metalness 0
      }
      geometry Cylinder {
        height 0.3
        radius 0.2
      }
    }
  ]
  name "obstacle_6"
  boundingObject Cylinder {
    height 0.3
    radius 0.2
  }
}
Solid {
  translation -0.8 -1.5 0.15
  children [
    Shape {
      appearance PBRAppearance {
        baseColor 0.7 0.2 0.9
        roughness 1
        metalness 0
      }
      geometry Cylinder {
        height 0.3
        radius 0.2
      }
    }
  ]
  name "obstacle_7"
  boundingObject Cylinder {
    height 0.3
    radius 0.2
  }
}
Solid {
  translation 0 -0.8 0.2
  children [
    Shape {
      appearance PBRAppearance {
        baseColor 0.9 0.5 0.5
        roughness 1
        metalness 0
      }
      geometry Cylinder {
        height 0.4
        radius 0.15
      }
    }
  ]
  name "obstacle_10"
  boundingObject Cylinder {
    height 0.4
    radius 0.15
  }
}
DEF SlamBot Robot {
  translation 0 0 0.1
  rotation 0 0 1 1.5708
  children [
    Shape {
      appearance PBRAppearance {
        baseColor 0.1 0.5 1
        roughness 1
        metalness 0
      }
      geometry DEF BODY_BOX Box {
        size 0.4 0.2 0.1
      }
    }
    Solid {
      translation 0.22 0 0.02
      children [
        Shape {
          appearance PBRAppearance {
            baseColor 0 1 0
            roughness 1
            metalness 0
          }
          geometry Box {
            size 0.05 0.1 0.02
          }
        }
      ]
      name "front_marker"
    }
    Lidar {
      translation 0 0 0.12
      horizontalResolution 360
      fieldOfView 6.28319
      verticalFieldOfView 0.1
      numberOfLayers 1
      minRange 0.05
      maxRange 4
    }
    Solid {
      translation 0 0 0.12
      children [
        Shape {
          appearance PBRAppearance {
            baseColor 0.1 0.1 0.1
            roughness 0.5
            metalness 0.8
          }
          geometry Cylinder {
            height 0.06
            radius 0.08
          }
        }
      ]
      name "lidar_housing"
    }
    HingeJoint {
      jointParameters HingeJointParameters {
        axis 0 1 0
        anchor 0 0.12 0
      }
      device [
        RotationalMotor {
          name "left_motor"
        }
        PositionSensor {
          name "left_encoder"
        }
      ]
      endPoint Solid {
        translation 0 0.12 0
        rotation 1 0 0 1.5708
        children [
          DEF WHEEL Shape {
            appearance PBRAppearance {
              baseColor 0.2 0.2 0.2
            }
            geometry Cylinder {
              height 0.04
              radius 0.08
            }
          }
        ]
        name "left_wheel"
        boundingObject USE WHEEL
        physics Physics {
        }
      }
    }
    HingeJoint {
      jointParameters HingeJointParameters {
        axis 0 1 0
        anchor 0 -0.12 0
      }
      device [
        RotationalMotor {
          name "right_motor"
        }
        PositionSensor {
          name "right_encoder"
        }
      ]
      endPoint Solid {
        translation 0 -0.12 0
        rotation 1 0 0 1.5708
        children [
          USE WHEEL
        ]
        name "right_wheel"
        boundingObject USE WHEEL
        physics Physics {
        }
      }
    }
    # Front Caster Wheel (Lowered to -0.06 to touch ground)
    Solid {
      translation 0.15 0 -0.06
      children [
        Shape {
          appearance PBRAppearance {
            baseColor 0.5 0.5 0.5
            roughness 0.5
          }
          geometry Sphere { radius 0.04 }
        }
      ]
      name "caster_front"
      boundingObject Sphere { radius 0.04 }
      physics Physics {}
    }

    # Back Caster Wheel (Lowered to -0.06 to touch ground)
    Solid {
      translation -0.15 0 -0.06
      children [
        Shape {
          appearance PBRAppearance {
            baseColor 0.5 0.5 0.5
            roughness 0.5
          }
          geometry Sphere { radius 0.04 }
        }
      ]
      name "caster_back"
      boundingObject Sphere { radius 0.04 }
      physics Physics {}
    }
    InertialUnit {
      name "imu"
    }
    Gyro {
    }
  ]
  name "SlamBot"
  boundingObject USE BODY_BOX
  physics Physics {
    density -1
    mass 5
  }
  controller "<extern>"
}
