#VRML_SIM R2025a utf8

EXTERNPROTO "https://raw.githubusercontent.com/cyberbotics/webots/R2025a/projects/objects/backgrounds/protos/TexturedBackground.proto"
EXTERNPROTO "https://raw.githubusercontent.com/cyberbotics/webots/R2025a/projects/objects/backgrounds/protos/TexturedBackgroundLight.proto"
EXTERNPROTO "https://raw.githubusercontent.com/cyberbotics/webots/R2025a/projects/objects/floors/protos/RectangleArena.proto"

WorldInfo {
  title "Level 4 - Visual Sensors (Camera)"
}

Viewpoint {
  orientation -0.5773502691896258 0.5773502691896258 0.5773502691896258 2.0944
  position 0 0 8
  follow "VisionBot"
}

TexturedBackground {
}

TexturedBackgroundLight {
}

RectangleArena {
  floorSize 4 4
  wallHeight 0.1
}

# --- Visual Targets: Multiple Colored Objects ---

# Red Ball
DEF RED_BALL Solid {
  translation 1.2 0 0.1
  children [
    Shape {
      appearance PBRAppearance {
        baseColor 1 0 0
        roughness 1
        metalness 0
      }
      geometry Sphere {
        radius 0.1
      }
    }
  ]
  name "red_ball"
  boundingObject Sphere { radius 0.1 }
  physics Physics { density -1 mass 0.2 }
}

# Green Cube
DEF GREEN_CUBE Solid {
  translation -1.2 1 0.1
  children [
    Shape {
      appearance PBRAppearance {
        baseColor 0 1 0
        roughness 1
        metalness 0
      }
      geometry Box {
        size 0.2 0.2 0.2
      }
    }
  ]
  name "green_cube"
  boundingObject Box { size 0.2 0.2 0.2 }
  physics Physics { density -1 mass 0.3 }
}

# Blue Cylinder
DEF BLUE_CYLINDER Solid {
  translation -1.2 -1 0.15
  children [
    Shape {
      appearance PBRAppearance {
        baseColor 0 0 1
        roughness 1
        metalness 0
      }
      geometry Cylinder {
        height 0.3
        radius 0.1
      }
    }
  ]
  name "blue_cylinder"
  boundingObject Cylinder { height 0.3 radius 0.1 }
  physics Physics { density -1 mass 0.25 }
}

# Yellow Box
DEF YELLOW_BOX Solid {
  translation 0 1.2 0.08
  children [
    Shape {
      appearance PBRAppearance {
        baseColor 1 1 0
        roughness 1
        metalness 0
      }
      geometry Box {
        size 0.15 0.15 0.15
      }
    }
  ]
  name "yellow_box"
  boundingObject Box { size 0.15 0.15 0.15 }
  physics Physics { density -1 mass 0.15 }
}

# Orange Ball (smaller)
DEF ORANGE_BALL Solid {
  translation 1 -1 0.07
  children [
    Shape {
      appearance PBRAppearance {
        baseColor 1 0.5 0
        roughness 1
        metalness 0
      }
      geometry Sphere {
        radius 0.07
      }
    }
  ]
  name "orange_ball"
  boundingObject Sphere { radius 0.07 }
  physics Physics { density -1 mass 0.1 }
}

# Purple Capsule
DEF PURPLE_CAPSULE Solid {
  translation 0 -1.2 0.1
  children [
    Shape {
      appearance PBRAppearance {
        baseColor 0.6 0 0.8
        roughness 1
        metalness 0
      }
      geometry Capsule {
        height 0.15
        radius 0.05
      }
    }
  ]
  name "purple_capsule"
  boundingObject Capsule { height 0.15 radius 0.05 }
  physics Physics { density -1 mass 0.12 }
}

# --- Robot with Camera ---
DEF VisionBot Robot {
  translation 0 0 0.1
  rotation 0 0 1 1.5708
  children [
    Shape {
      appearance PBRAppearance {
        baseColor 0.1 0.5 1
        roughness 1
        metalness 0
      }
      geometry DEF BODY_BOX Box {
        size 0.4 0.2 0.1
      }
    }
    
    # Front Marker
    Solid {
      translation 0.22 0 0.02
      name "front_marker"
      children [
        Shape {
          appearance PBRAppearance {
            baseColor 0 1 0
            roughness 1
            metalness 0
          }
          geometry Box {
            size 0.05 0.1 0.02
          }
        }
      ]
    }
    
    # --- NEW SENSOR: RGB Camera ---
    Camera {
      translation 0.2 0 0.1  # Mounted on front top
      rotation 0 0 1 0       # Facing along X-axis (robot front)
      name "camera"
      fieldOfView 1.0        # Wide view angle approximately 57 degrees
      width 640
      height 480
      recognitionColors [ 1 0 0 ] # Helps detect red color (if recognition enabled)
    }
    
    # Wheels
    HingeJoint {
      jointParameters HingeJointParameters { axis 0 1 0 anchor 0 0.12 0 }
      device [ RotationalMotor { name "left_motor" } ]
      endPoint Solid {
        translation 0 0.12 0
        rotation 1 0 0 1.5708
        name "left_wheel"
        children [
          DEF WHEEL Shape {
            appearance PBRAppearance { baseColor 0.2 0.2 0.2 }
            geometry Cylinder { height 0.04 radius 0.08 }
          }
        ]
        boundingObject USE WHEEL
        physics Physics {}
      }
    }
    
    HingeJoint {
      jointParameters HingeJointParameters { axis 0 1 0 anchor 0 -0.12 0 }
      device [ RotationalMotor { name "right_motor" } ]
      endPoint Solid {
        translation 0 -0.12 0
        rotation 1 0 0 1.5708
        name "right_wheel"
        children [ USE WHEEL ]
        boundingObject USE WHEEL
        physics Physics {}
      }
    }
    
    BallJoint {
      jointParameters BallJointParameters { anchor -0.15 0 -0.04 }
      endPoint Solid {
        translation -0.15 0 -0.04
        name "ball_wheel_rear"
        children [
          Shape {
            appearance PBRAppearance { baseColor 0.5 0.5 0.5 roughness 0.3 metalness 0.1 }
            geometry Sphere { radius 0.04 }
          }
        ]
        boundingObject Sphere { radius 0.04 }
        physics Physics { density -1 mass 0.1 }
      }
    }
    BallJoint {
      jointParameters BallJointParameters { anchor 0.15 0 -0.04 }
      endPoint Solid {
        translation 0.15 0 -0.04
        name "ball_wheel_front"
        children [
          Shape {
            appearance PBRAppearance { baseColor 0.5 0.5 0.5 roughness 0.3 metalness 0.1 }
            geometry Sphere { radius 0.04 }
          }
        ]
        boundingObject Sphere { radius 0.04 }
        physics Physics { density -1 mass 0.1 }
      }
    }
    
    # Previous Sensors (Still useful!)
    DistanceSensor { translation 0.2 0 0.06 rotation 0 0 1 0 name "ds_front" type "infra-red" }
    InertialUnit { name "imu" }
    Gyro { name "gyro" }
  ]
  
  name "VisionBot"
  boundingObject USE BODY_BOX
  physics Physics {
    density -1
    mass 5
  }
  controller "<extern>"
}